[2024-06-24T02:18:36.705+0000] {local_task_job_runner.py:120} INFO - ::group::Pre task execution logs
[2024-06-24T02:18:36.756+0000] {taskinstance.py:2076} INFO - Dependencies all met for dep_context=non-requeueable deps ti=<TaskInstance: postgres_operator_2.load_parquet_to_postgres scheduled__2024-06-24T02:13:00+00:00 [queued]>
[2024-06-24T02:18:36.771+0000] {taskinstance.py:2076} INFO - Dependencies all met for dep_context=requeueable deps ti=<TaskInstance: postgres_operator_2.load_parquet_to_postgres scheduled__2024-06-24T02:13:00+00:00 [queued]>
[2024-06-24T02:18:36.773+0000] {taskinstance.py:2306} INFO - Starting attempt 1 of 6
[2024-06-24T02:18:36.789+0000] {taskinstance.py:2330} INFO - Executing <Task(PythonOperator): load_parquet_to_postgres> on 2024-06-24 02:13:00+00:00
[2024-06-24T02:18:36.803+0000] {warnings.py:112} WARNING - /home/***/.local/lib/python3.12/site-packages/***/task/task_runner/standard_task_runner.py:61: DeprecationWarning: This process (pid=1412) is multi-threaded, use of fork() may lead to deadlocks in the child.
  pid = os.fork()

[2024-06-24T02:18:36.804+0000] {standard_task_runner.py:90} INFO - Running: ['***', 'tasks', 'run', 'postgres_operator_2', 'load_parquet_to_postgres', 'scheduled__2024-06-24T02:13:00+00:00', '--job-id', '39', '--raw', '--subdir', 'DAGS_FOLDER/dag.py', '--cfg-path', '/tmp/tmpat2sniz7']
[2024-06-24T02:18:36.811+0000] {standard_task_runner.py:91} INFO - Job 39: Subtask load_parquet_to_postgres
[2024-06-24T02:18:36.808+0000] {standard_task_runner.py:63} INFO - Started process 1416 to run task
[2024-06-24T02:18:36.925+0000] {task_command.py:426} INFO - Running <TaskInstance: postgres_operator_2.load_parquet_to_postgres scheduled__2024-06-24T02:13:00+00:00 [running]> on host 18d040e2d413
[2024-06-24T02:18:37.096+0000] {taskinstance.py:2648} INFO - Exporting env vars: AIRFLOW_CTX_DAG_OWNER='***' AIRFLOW_CTX_DAG_ID='postgres_operator_2' AIRFLOW_CTX_TASK_ID='load_parquet_to_postgres' AIRFLOW_CTX_EXECUTION_DATE='2024-06-24T02:13:00+00:00' AIRFLOW_CTX_TRY_NUMBER='1' AIRFLOW_CTX_DAG_RUN_ID='scheduled__2024-06-24T02:13:00+00:00'
[2024-06-24T02:18:37.105+0000] {taskinstance.py:430} INFO - ::endgroup::
[2024-06-24T02:18:38.684+0000] {base.py:84} INFO - Using connection ID 'postgres_localhost' for task execution.
[2024-06-24T02:18:38.688+0000] {base.py:84} INFO - Using connection ID 'postgres_localhost' for task execution.
[2024-06-24T02:18:38.689+0000] {base.py:84} INFO - Using connection ID 'postgres_localhost' for task execution.
[2024-06-24T02:18:38.703+0000] {base.py:84} INFO - Using connection ID 'postgres_localhost' for task execution.
[2024-06-24T02:18:38.707+0000] {base.py:84} INFO - Using connection ID 'postgres_localhost' for task execution.
[2024-06-24T02:18:38.708+0000] {base.py:84} INFO - Using connection ID 'postgres_localhost' for task execution.
[2024-06-24T02:18:38.710+0000] {base.py:84} INFO - Using connection ID 'postgres_localhost' for task execution.
[2024-06-24T02:18:38.715+0000] {base.py:84} INFO - Using connection ID 'postgres_localhost' for task execution.
[2024-06-24T02:18:38.716+0000] {base.py:84} INFO - Using connection ID 'postgres_localhost' for task execution.
[2024-06-24T02:18:38.716+0000] {base.py:84} INFO - Using connection ID 'postgres_localhost' for task execution.
[2024-06-24T02:18:38.750+0000] {base.py:84} INFO - Using connection ID 'postgres_localhost' for task execution.
[2024-06-24T02:18:38.749+0000] {base.py:84} INFO - Using connection ID 'postgres_localhost' for task execution.
[2024-06-24T02:18:38.787+0000] {base.py:84} INFO - Using connection ID 'postgres_localhost' for task execution.
[2024-06-24T02:18:38.790+0000] {base.py:84} INFO - Using connection ID 'postgres_localhost' for task execution.
[2024-06-24T02:18:38.791+0000] {base.py:84} INFO - Using connection ID 'postgres_localhost' for task execution.
[2024-06-24T02:18:38.806+0000] {base.py:84} INFO - Using connection ID 'postgres_localhost' for task execution.
[2024-06-24T02:18:52.286+0000] {local_task_job_runner.py:310} WARNING - State of this instance has been externally set to None. Terminating instance.
[2024-06-24T02:18:52.302+0000] {local_task_job_runner.py:222} INFO - ::endgroup::
[2024-06-24T02:18:52.314+0000] {process_utils.py:132} INFO - Sending 15 to group 1416. PIDs of all processes in the group: [1416]
[2024-06-24T02:18:52.319+0000] {process_utils.py:87} INFO - Sending the signal 15 to group 1416
[2024-06-24T02:18:52.387+0000] {taskinstance.py:2611} ERROR - Received SIGTERM. Terminating subprocesses.
[2024-06-24T02:18:52.417+0000] {taskinstance.py:441} INFO - ::group::Post task execution logs
[2024-06-24T02:18:52.650+0000] {taskinstance.py:2905} ERROR - Task failed with exception
Traceback (most recent call last):
  File "/home/airflow/.local/lib/python3.12/site-packages/airflow/models/taskinstance.py", line 465, in _execute_task
    result = _execute_callable(context=context, **execute_callable_kwargs)
             ^^^^^^^^^^^^^^^^^^^^^^^^^^^^^^^^^^^^^^^^^^^^^^^^^^^^^^^^^^^^^
  File "/home/airflow/.local/lib/python3.12/site-packages/airflow/models/taskinstance.py", line 432, in _execute_callable
    return execute_callable(context=context, **execute_callable_kwargs)
           ^^^^^^^^^^^^^^^^^^^^^^^^^^^^^^^^^^^^^^^^^^^^^^^^^^^^^^^^^^^^
  File "/home/airflow/.local/lib/python3.12/site-packages/airflow/models/baseoperator.py", line 401, in wrapper
    return func(self, *args, **kwargs)
           ^^^^^^^^^^^^^^^^^^^^^^^^^^^
  File "/home/airflow/.local/lib/python3.12/site-packages/airflow/operators/python.py", line 235, in execute
    return_value = self.execute_callable()
                   ^^^^^^^^^^^^^^^^^^^^^^^
  File "/home/airflow/.local/lib/python3.12/site-packages/airflow/operators/python.py", line 252, in execute_callable
    return self.python_callable(*self.op_args, **self.op_kwargs)
           ^^^^^^^^^^^^^^^^^^^^^^^^^^^^^^^^^^^^^^^^^^^^^^^^^^^^^
  File "/opt/airflow/dags/dag.py", line 43, in load_parquet_to_postgres
    with ThreadPoolExecutor(max_workers=max_workers) as executor:
  File "/usr/local/lib/python3.12/concurrent/futures/_base.py", line 647, in __exit__
    self.shutdown(wait=True)
  File "/usr/local/lib/python3.12/concurrent/futures/thread.py", line 238, in shutdown
    t.join()
  File "/usr/local/lib/python3.12/threading.py", line 1147, in join
    self._wait_for_tstate_lock()
  File "/usr/local/lib/python3.12/threading.py", line 1167, in _wait_for_tstate_lock
    if lock.acquire(block, timeout):
       ^^^^^^^^^^^^^^^^^^^^^^^^^^^^
  File "/home/airflow/.local/lib/python3.12/site-packages/airflow/models/taskinstance.py", line 2613, in signal_handler
    raise AirflowTaskTerminated("Task received SIGTERM signal")
airflow.exceptions.AirflowTaskTerminated: Task received SIGTERM signal
[2024-06-24T02:18:53.707+0000] {taskinstance.py:1206} INFO - Marking task as UP_FOR_RETRY. dag_id=postgres_operator_2, task_id=load_parquet_to_postgres, run_id=scheduled__2024-06-24T02:13:00+00:00, execution_date=20240624T021300, start_date=20240624T021836, end_date=20240624T021853
[2024-06-24T02:18:54.696+0000] {standard_task_runner.py:110} ERROR - Failed to execute job 39 for task load_parquet_to_postgres ((psycopg2.errors.ForeignKeyViolation) insert or update on table "task_fail" violates foreign key constraint "task_fail_ti_fkey"
DETAIL:  Key (dag_id, task_id, run_id, map_index)=(postgres_operator_2, load_parquet_to_postgres, scheduled__2024-06-24T02:13:00+00:00, -1) is not present in table "task_instance".

[SQL: INSERT INTO task_fail (task_id, dag_id, run_id, map_index, start_date, end_date, duration) VALUES (%(task_id)s, %(dag_id)s, %(run_id)s, %(map_index)s, %(start_date)s, %(end_date)s, %(duration)s) RETURNING task_fail.id]
[parameters: {'task_id': 'load_parquet_to_postgres', 'dag_id': 'postgres_operator_2', 'run_id': 'scheduled__2024-06-24T02:13:00+00:00', 'map_index': -1, 'start_date': datetime.datetime(2024, 6, 24, 2, 18, 36, 761717, tzinfo=Timezone('UTC')), 'end_date': datetime.datetime(2024, 6, 24, 2, 18, 53, 705187, tzinfo=Timezone('UTC')), 'duration': 16}]
(Background on this error at: https://sqlalche.me/e/14/gkpj); 1416)
[2024-06-24T02:18:54.886+0000] {process_utils.py:80} INFO - Process psutil.Process(pid=1416, status='terminated', exitcode=1, started='02:18:36') (1416) terminated with exit code 1
